<?xml version="1.0" encoding="utf-8"?>
<!-- This URDF was automatically created by SolidWorks to URDF Exporter! Originally created by Stephen Brawner (brawner@gmail.com) 
     Commit Version: 1.6.0-1-g15f4949  Build Version: 1.6.7594.29634
     For more information, please see http://wiki.ros.org/sw_urdf_exporter -->
<robot
  name="butter_robot_v2">
  <!-- ***************************************** camera ********************************************************************** -->
  <gazebo reference="camera_link">
    <sensor type="camera" name="camera">
      <update_rate>30.0</update_rate>
      <camera name="head">
        <horizontal_fov>1.3962634</horizontal_fov>
        <image>
          <width>800</width>
          <height>800</height>
          <format>R8G8B8</format>
        </image>
        <clip>
          <near>0.02</near>
          <far>300</far>
        </clip>
        <noise>
          <type>gaussian</type>
          <!-- Noise is sampled independently per pixel on each frame.
               That pixel's noise value is added to each of its color
               channels, which at that point lie in the range [0,1]. -->
          <mean>0.0</mean>
          <stddev>0.007</stddev>
        </noise>
      </camera>
      <plugin name="camera_controller" filename="libgazebo_ros_camera.so">
        <alwaysOn>true</alwaysOn>
        <updateRate>0.0</updateRate>
        <cameraName>butter_edrom/camera</cameraName>
        <imageTopicName>image_raw</imageTopicName>
        <cameraInfoTopicName>camera_info</cameraInfoTopicName>
        <frameName>camera_link</frameName>
        <hackBaseline>0.07</hackBaseline>
        <distortionK1>0.0</distortionK1>
        <distortionK2>0.0</distortionK2>
        <distortionK3>0.0</distortionK3>
        <distortionT1>0.0</distortionT1>
        <distortionT2>0.0</distortionT2>
      </plugin>
    </sensor>
  </gazebo>
  
   <!-- Faz a camera aparecer no modelo -->
  <link name="camera_link">
    <visual>
      <origin xyz="0 0 0" rpy="0 0 0"/>
      <geometry>
    <box size="0.005 0.005 0.005"/>   <!-- Gera o tamanho do bloco que virtualiza a camera-->
      </geometry>
      <material name="red"/>
    </visual>

    <inertial>
      <mass value="1e-5" />
      <origin xyz="0 0 0" rpy="0 0 0"/>
      <inertia ixx="1e-6" ixy="0" ixz="0" iyy="1e-6" iyz="0" izz="1e-6" />
    </inertial>
  </link>
  
  <joint name="camera_joint" type="fixed">
    <axis xyz="0 0 1" />    
    <origin xyz="10.0 10.0 0.0" rpy="0 -1.5708 0"/>   <!-- Ponto de origem e eixo de visualizacao da camera -->
    <parent link="cam_Link"/><!-- Vincula a referencia da peca a referencia da camera. Onde esta "head" adicione o nome da sua peca -->
    <child link="camera_link"/>
  </joint>
  <!-- ***************************************** camera ********************************************************************** -->

  <link
    name="base_link">
    <inertial>
      <origin
        xyz="-0.0487232105091282 -5.37824504816871E-18 -0.0118259744664555"
        rpy="0 0 0" />
      <mass
        value="0.0034973712165487" />
      <inertia
        ixx="5.20346178705524E-07"
        ixy="7.69640967170829E-23"
        ixz="4.8723608968141E-23"
        iyy="2.48416312565321E-07"
        iyz="-5.06082215972284E-23"
        izz="6.59980876650952E-07" />
    </inertial>
    <visual>
      <origin
        xyz="0 0 0"
        rpy="0 0 0" />
      <geometry>
        <mesh
          filename="package://butter_robot_v2/meshes/base_link.STL" />
      </geometry>
      <material
        name="">
        <color
          rgba="0.792156862745098 0.819607843137255 0.933333333333333 1" />
      </material>
    </visual>
    <collision>
      <origin
        xyz="0 0 0"
        rpy="0 0 0" />
      <geometry>
        <mesh
          filename="package://butter_robot_v2/meshes/base_link.STL" />
      </geometry>
    </collision>
  </link>
  <link
    name="wheel_Link_1">
    <inertial>
      <origin
        xyz="0.00580202353065885 5.20417042793042E-18 0"
        rpy="0 0 0" />
      <mass
        value="0.000683833835739056" />
      <inertia
        ixx="1.40180766956566E-08"
        ixy="-7.28605191563402E-26"
        ixz="4.20383474979454E-25"
        iyy="8.69990825940298E-09"
        iyz="-5.49299625523495E-26"
        izz="8.69990825940298E-09" />
    </inertial>
    <visual>
      <origin
        xyz="0 0 0"
        rpy="0 0 0" />
      <geometry>
        <mesh
          filename="package://butter_robot_v2/meshes/wheel_Link_1.STL" />
      </geometry>
      <material
        name="">
        <color
          rgba="0.792156862745098 0.819607843137255 0.933333333333333 1" />
      </material>
    </visual>
    <collision>
      <origin
        xyz="0 0 0"
        rpy="0 0 0" />
      <geometry>
        <mesh
          filename="package://butter_robot_v2/meshes/wheel_Link_1.STL" />
      </geometry>
    </collision>
  </link>
  <joint
    name="wheel_right_front"
    type="continuous">
    <origin
      xyz="-0.0577232105091282 -0.00799999999999999 -0.0135822784810127"
      rpy="1.56938291651632 0 3.14159265358979" />
    <parent
      link="base_link" />
    <child
      link="wheel_Link_1" />
    <axis
      xyz="1 0 0" />
  </joint>
  <link
    name="wheel_Link_2">
    <inertial>
      <origin
        xyz="0.00580202353065885 6.93889390390723E-18 0"
        rpy="0 0 0" />
      <mass
        value="0.000683833835739056" />
      <inertia
        ixx="1.40180766956566E-08"
        ixy="4.07418770721579E-26"
        ixz="-1.97837744102725E-26"
        iyy="8.69990825940298E-09"
        iyz="-4.79459140047986E-27"
        izz="8.69990825940298E-09" />
    </inertial>
    <visual>
      <origin
        xyz="0 0 0"
        rpy="0 0 0" />
      <geometry>
        <mesh
          filename="package://butter_robot_v2/meshes/wheel_Link_2.STL" />
      </geometry>
      <material
        name="">
        <color
          rgba="0.792156862745098 0.819607843137255 0.933333333333333 1" />
      </material>
    </visual>
    <collision>
      <origin
        xyz="0 0 0"
        rpy="0 0 0" />
      <geometry>
        <mesh
          filename="package://butter_robot_v2/meshes/wheel_Link_2.STL" />
      </geometry>
    </collision>
  </link>
  <joint
    name="wheel_right_back"
    type="continuous">
    <origin
      xyz="-0.0577232105091282 0.00800000000000001 -0.0135822784810127"
      rpy="1.5707963267949 0 3.14159265358979" />
    <parent
      link="base_link" />
    <child
      link="wheel_Link_2" />
    <axis
      xyz="1 0 0" />
  </joint>
  <link
    name="wheel_Link_3">
    <inertial>
      <origin
        xyz="-0.00269797646934115 3.46944695195361E-18 0"
        rpy="0 0 0" />
      <mass
        value="0.000683833835739055" />
      <inertia
        ixx="1.40180766956566E-08"
        ixy="-6.30620677877619E-26"
        ixz="1.97310294333372E-25"
        iyy="8.69990825940297E-09"
        iyz="8.27988406119974E-25"
        izz="8.69990825940297E-09" />
    </inertial>
    <visual>
      <origin
        xyz="0 0 0"
        rpy="0 0 0" />
      <geometry>
        <mesh
          filename="package://butter_robot_v2/meshes/wheel_Link_3.STL" />
      </geometry>
      <material
        name="">
        <color
          rgba="0.792156862745098 0.819607843137255 0.933333333333333 1" />
      </material>
    </visual>
    <collision>
      <origin
        xyz="0 0 0"
        rpy="0 0 0" />
      <geometry>
        <mesh
          filename="package://butter_robot_v2/meshes/wheel_Link_3.STL" />
      </geometry>
    </collision>
  </link>
  <joint
    name="wheel_left_front"
    type="continuous">
    <origin
      xyz="-0.0312232105091282 -0.00799999999999999 -0.0135822784810127"
      rpy="1.57220973707347 0 0" />
    <parent
      link="base_link" />
    <child
      link="wheel_Link_3" />
    <axis
      xyz="1 0 0" />
  </joint>
  <link
    name="wheel_Link_4">
    <inertial>
      <origin
        xyz="-0.00269797646934115 3.46944695195361E-18 0"
        rpy="0 0 0" />
      <mass
        value="0.000683833835739055" />
      <inertia
        ixx="1.40180766956566E-08"
        ixy="-4.74613062424027E-27"
        ixz="-2.7704806913854E-26"
        iyy="8.69990825940297E-09"
        iyz="9.60937764013461E-28"
        izz="8.69990825940297E-09" />
    </inertial>
    <visual>
      <origin
        xyz="0 0 0"
        rpy="0 0 0" />
      <geometry>
        <mesh
          filename="package://butter_robot_v2/meshes/wheel_Link_4.STL" />
      </geometry>
      <material
        name="">
        <color
          rgba="0.792156862745098 0.819607843137255 0.933333333333333 1" />
      </material>
    </visual>
    <collision>
      <origin
        xyz="0 0 0"
        rpy="0 0 0" />
      <geometry>
        <mesh
          filename="package://butter_robot_v2/meshes/wheel_Link_4.STL" />
      </geometry>
    </collision>
  </link>
  <joint
    name="wheel_left_back"
    type="continuous">
    <origin
      xyz="-0.0312232105091282 0.00800000000000001 -0.0135822784810127"
      rpy="1.5707963267949 0 0" />
    <parent
      link="base_link" />
    <child
      link="wheel_Link_4" />
    <axis
      xyz="1 0 0" />
  </joint>
  <link
    name="body_Link">
    <inertial>
      <origin
        xyz="-0.0140672325960871 -0.0320785135940926 -0.00208481753621507"
        rpy="0 0 0" />
      <mass
        value="0.0127431329836156" />
      <inertia
        ixx="1.26968265952612E-06"
        ixy="3.02902040990022E-09"
        ixz="3.8403200535179E-11"
        iyy="1.28048557499872E-06"
        iyz="-1.05212136210703E-08"
        izz="1.70855532641506E-06" />
    </inertial>
    <visual>
      <origin
        xyz="0 0 0"
        rpy="0 0 0" />
      <geometry>
        <mesh
          filename="package://butter_robot_v2/meshes/body_Link.STL" />
      </geometry>
      <material
        name="">
        <color
          rgba="0.792156862745098 0.819607843137255 0.933333333333333 1" />
      </material>
    </visual>
    <collision>
      <origin
        xyz="0 0 0"
        rpy="0 0 0" />
      <geometry>
        <mesh
          filename="package://butter_robot_v2/meshes/body_Link.STL" />
      </geometry>
    </collision>
  </link>
  <joint
    name="body"
    type="continuous">
    <origin
      xyz="-0.0349732105091282 0 0.000417721518987318"
      rpy="-1.58560758722881 0 0" />
    <parent
      link="base_link" />
    <child
      link="body_Link" />
    <axis
      xyz="1 0 0" />
  </joint>
  <link
    name="right_arm_Link">
    <inertial>
      <origin
        xyz="0.00200212954468117 -0.0158190795000211 -0.00299718317271274"
        rpy="0 0 0" />
      <mass
        value="0.000627506454434052" />
      <inertia
        ixx="2.36680647208694E-08"
        ixy="-2.80967748338719E-10"
        ixz="-5.47833165126233E-11"
        iyy="3.34542222546291E-09"
        iyz="-3.62580537916178E-09"
        izz="2.17089060625663E-08" />
    </inertial>
    <visual>
      <origin
        xyz="0 0 0"
        rpy="0 0 0" />
      <geometry>
        <mesh
          filename="package://butter_robot_v2/meshes/right_arm_Link.STL" />
      </geometry>
      <material
        name="">
        <color
          rgba="0.792156862745098 0.819607843137255 0.933333333333333 1" />
      </material>
    </visual>
    <collision>
      <origin
        xyz="0 0 0"
        rpy="0 0 0" />
      <geometry>
        <mesh
          filename="package://butter_robot_v2/meshes/right_arm_Link.STL" />
      </geometry>
    </collision>
  </link>
  <joint
    name="right_arm"
    type="continuous">
    <origin
      xyz="-0.0285 -0.0354262807909886 0.00125"
      rpy="-0.227945600217958 0 3.14159265358979" />
    <parent
      link="body_Link" />
    <child
      link="right_arm_Link" />
    <axis
      xyz="1 0 0" />
  </joint>
  <link
    name="right_shoulder_Link">
    <inertial>
      <origin
        xyz="3.64810401316806E-06 0.0120826891216374 0.00235589239828446"
        rpy="0 0 0" />
      <mass
        value="0.000366300694171296" />
      <inertia
        ixx="1.9616555656272E-08"
        ixy="-2.80967748338718E-10"
        ixz="-5.4783316512623E-11"
        iyy="2.42760026770147E-09"
        iyz="-3.10066525054526E-09"
        izz="1.77254432409598E-08" />
    </inertial>
    <visual>
      <origin
        xyz="0 0 0"
        rpy="0 0 0" />
      <geometry>
        <mesh
          filename="package://butter_robot_v2/meshes/right_shoulder_Link.STL" />
      </geometry>
      <material
        name="">
        <color
          rgba="0.792156862745098 0.819607843137255 0.933333333333333 1" />
      </material>
    </visual>
    <collision>
      <origin
        xyz="0 0 0"
        rpy="0 0 0" />
      <geometry>
        <mesh
          filename="package://butter_robot_v2/meshes/right_shoulder_Link.STL" />
      </geometry>
    </collision>
  </link>
  <joint
    name="right_shoulder"
    type="fixed">
    <origin
      xyz="0.002 -0.0196854653686963 -0.00383828779768512"
      rpy="0 0 0" />
    <parent
      link="right_arm_Link" />
    <child
      link="right_shoulder_Link" />
    <axis
      xyz="0 0 0" />
  </joint>
  <link
    name="right_elbow_Link">
    <inertial>
      <origin
        xyz="1.12757025938492E-17 -0.00612354471534082 -1.38777878078145E-17"
        rpy="0 0 0" />
      <mass
        value="0.000222625340555313" />
      <inertia
        ixx="3.88047932552135E-09"
        ixy="5.53177034644837E-24"
        ixz="1.17748888959594E-25"
        iyy="7.6269481701323E-10"
        iyz="1.03641274404643E-24"
        izz="3.87588303334026E-09" />
    </inertial>
    <visual>
      <origin
        xyz="0 0 0"
        rpy="0 0 0" />
      <geometry>
        <mesh
          filename="package://butter_robot_v2/meshes/right_elbow_Link.STL" />
      </geometry>
      <material
        name="">
        <color
          rgba="0.792156862745098 0.819607843137255 0.933333333333333 1" />
      </material>
    </visual>
    <collision>
      <origin
        xyz="0 0 0"
        rpy="0 0 0" />
      <geometry>
        <mesh
          filename="package://butter_robot_v2/meshes/right_elbow_Link.STL" />
      </geometry>
    </collision>
  </link>
  <joint
    name="right_elbow"
    type="fixed">
    <origin
      xyz="0 0 0"
      rpy="1.5707963267949 -1.409622985638 -1.5707963267949" />
    <parent
      link="right_shoulder_Link" />
    <child
      link="right_elbow_Link" />
    <axis
      xyz="0 0 0" />
  </joint>
  <link
    name="right_hand_Link">
    <inertial>
      <origin
        xyz="0 -0.00122214723202105 0.000231252080889962"
        rpy="0 0 0" />
      <mass
        value="3.85804197074431E-05" />
      <inertia
        ixx="1.75626031257094E-10"
        ixy="-2.84287539378873E-26"
        ixz="1.51381554780657E-27"
        iyy="6.74412852470547E-11"
        iyz="1.10795333563524E-11"
        izz="1.90669351586239E-10" />
    </inertial>
    <visual>
      <origin
        xyz="0 0 0"
        rpy="0 0 0" />
      <geometry>
        <mesh
          filename="package://butter_robot_v2/meshes/right_hand_Link.STL" />
      </geometry>
      <material
        name="">
        <color
          rgba="0.792156862745098 0.819607843137255 0.933333333333333 1" />
      </material>
    </visual>
    <collision>
      <origin
        xyz="0 0 0"
        rpy="0 0 0" />
      <geometry>
        <mesh
          filename="package://butter_robot_v2/meshes/right_hand_Link.STL" />
      </geometry>
    </collision>
  </link>
  <joint
    name="right_hand"
    type="fixed">
    <origin
      xyz="-1.15961164218492E-05 -0.0159999327627815 0"
      rpy="3.12999627726406 -1.5707963267949 0" />
    <parent
      link="right_elbow_Link" />
    <child
      link="right_hand_Link" />
    <axis
      xyz="0 0 0" />
  </joint>
  <link
    name="left_arm_Link">
    <inertial>
      <origin
        xyz="0.00200212954468116 -0.0157809086244819 -0.00319023879120293"
        rpy="0 0 0" />
      <mass
        value="0.000627506454434052" />
      <inertia
        ixx="2.36680647208694E-08"
        ixy="-2.80967748338716E-10"
        ixz="-5.47833165126226E-11"
        iyy="3.42304890573103E-09"
        iyz="-3.81413682704257E-09"
        izz="2.16312793822981E-08" />
    </inertial>
    <visual>
      <origin
        xyz="0 0 0"
        rpy="0 0 0" />
      <geometry>
        <mesh
          filename="package://butter_robot_v2/meshes/left_arm_Link.STL" />
      </geometry>
      <material
        name="">
        <color
          rgba="0.792156862745098 0.819607843137255 0.933333333333333 1" />
      </material>
    </visual>
    <collision>
      <origin
        xyz="0 0 0"
        rpy="0 0 0" />
      <geometry>
        <mesh
          filename="package://butter_robot_v2/meshes/left_arm_Link.STL" />
      </geometry>
    </collision>
  </link>
  <joint
    name="left_arm"
    type="continuous">
    <origin
      xyz="0.000500000000000028 -0.0354262807909886 0.00125"
      rpy="2.92379206079219 0 0" />
    <parent
      link="body_Link" />
    <child
      link="left_arm_Link" />
    <axis
      xyz="1 0 0" />
  </joint>
  <link
    name="left_shoulder_Link">
    <inertial>
      <origin
        xyz="3.64810401316806E-06 0.0120826891216374 0.00235589239828446"
        rpy="0 0 0" />
      <mass
        value="0.000366300694171296" />
      <inertia
        ixx="1.9616555656272E-08"
        ixy="-2.80967748338717E-10"
        ixz="-5.47833165126227E-11"
        iyy="2.42760026770147E-09"
        iyz="-3.10066525054527E-09"
        izz="1.77254432409598E-08" />
    </inertial>
    <visual>
      <origin
        xyz="0 0 0"
        rpy="0 0 0" />
      <geometry>
        <mesh
          filename="package://butter_robot_v2/meshes/left_shoulder_Link.STL" />
      </geometry>
      <material
        name="">
        <color
          rgba="0.792156862745098 0.819607843137255 0.933333333333333 1" />
      </material>
    </visual>
    <collision>
      <origin
        xyz="0 0 0"
        rpy="0 0 0" />
      <geometry>
        <mesh
          filename="package://butter_robot_v2/meshes/left_shoulder_Link.STL" />
      </geometry>
    </collision>
  </link>
  <joint
    name="left_shoulder"
    type="fixed">
    <origin
      xyz="0.00199999999999999 -0.0196854653686963 -0.00383828779768512"
      rpy="0 0 0" />
    <parent
      link="left_arm_Link" />
    <child
      link="left_shoulder_Link" />
    <axis
      xyz="0 0 0" />
  </joint>
  <link
    name="left_elbow_Link">
    <inertial>
      <origin
        xyz="-2.12937306676153E-16 -0.00612354471534082 0"
        rpy="0 0 0" />
      <mass
        value="0.000222625340555313" />
      <inertia
        ixx="3.88047932552134E-09"
        ixy="-1.09087977377286E-22"
        ixz="4.32733688337115E-26"
        iyy="7.62694817013227E-10"
        iyz="-5.39262600462513E-25"
        izz="3.87588303334024E-09" />
    </inertial>
    <visual>
      <origin
        xyz="0 0 0"
        rpy="0 0 0" />
      <geometry>
        <mesh
          filename="package://butter_robot_v2/meshes/left_elbow_Link.STL" />
      </geometry>
      <material
        name="">
        <color
          rgba="0.792156862745098 0.819607843137255 0.933333333333333 1" />
      </material>
    </visual>
    <collision>
      <origin
        xyz="0 0 0"
        rpy="0 0 0" />
      <geometry>
        <mesh
          filename="package://butter_robot_v2/meshes/left_elbow_Link.STL" />
      </geometry>
    </collision>
  </link>
  <joint
    name="left_elbow"
    type="fixed">
    <origin
      xyz="0 0 0"
      rpy="1.5707963267949 -1.33972000515522 -1.5707963267949" />
    <parent
      link="left_shoulder_Link" />
    <child
      link="left_elbow_Link" />
    <axis
      xyz="0 0 0" />
  </joint>
  <link
    name="left_hand_Link">
    <inertial>
      <origin
        xyz="-0.00199999999999996 -0.00186356281811588 -0.000719277600614088"
        rpy="0 0 0" />
      <mass
        value="3.8580419707443E-05" />
      <inertia
        ixx="1.75626031257094E-10"
        ixy="5.97708256770315E-26"
        ixz="1.00560852774582E-27"
        iyy="6.74412852470546E-11"
        iyz="1.10795333563524E-11"
        izz="1.90669351586239E-10" />
    </inertial>
    <visual>
      <origin
        xyz="0 0 0"
        rpy="0 0 0" />
      <geometry>
        <mesh
          filename="package://butter_robot_v2/meshes/left_hand_Link.STL" />
      </geometry>
      <material
        name="">
        <color
          rgba="0.792156862745098 0.819607843137255 0.933333333333333 1" />
      </material>
    </visual>
    <collision>
      <origin
        xyz="0 0 0"
        rpy="0 0 0" />
      <geometry>
        <mesh
          filename="package://butter_robot_v2/meshes/left_hand_Link.STL" />
      </geometry>
    </collision>
  </link>
  <joint
    name="leftt_hand"
    type="fixed">
    <origin
      xyz="0.000947982602003767 -0.0153652648951283 -0.00199999999999995"
      rpy="0.0070375669506361 1.5707963267949 0" />
    <parent
      link="left_elbow_Link" />
    <child
      link="left_hand_Link" />
    <axis
      xyz="0 0 0" />
  </joint>
  <link
    name="cam_Link">
    <inertial>
      <origin
        xyz="0 0 0.00385008282716731"
        rpy="0 0 0" />
      <mass
        value="0.00142235607391278" />
      <inertia
        ixx="2.91627383140743E-08"
        ixy="-1.48570907445704E-25"
        ixz="1.11152394811813E-24"
        iyy="2.91627383140743E-08"
        iyz="-2.4556924435168E-24"
        izz="4.50444499914817E-08" />
    </inertial>
    <visual>
      <origin
        xyz="0 0 0"
        rpy="0 0 0" />
      <geometry>
        <mesh
          filename="package://butter_robot_v2/meshes/cam_Link.STL" />
      </geometry>
      <material
        name="">
        <color
          rgba="0.792156862745098 0.819607843137255 0.933333333333333 1" />
      </material>
    </visual>
    <collision>
      <origin
        xyz="0 0 0"
        rpy="0 0 0" />
      <geometry>
        <mesh
          filename="package://butter_robot_v2/meshes/cam_Link.STL" />
      </geometry>
    </collision>
  </link>
  <joint
    name="cam"
    type="fixed">
    <origin
      xyz="-0.01405 -0.0353762807909886 -0.01675"
      rpy="3.14159265358979 0 0.027684807670287" />
    <parent
      link="body_Link" />
    <child
      link="cam_Link" />
    <axis
      xyz="0 0 0" />
  </joint>
</robot>
