<?xml version="1.0" encoding="utf-8"?>
<!-- This URDF was automatically created by SolidWorks to URDF Exporter! Originally created by Stephen Brawner (brawner@gmail.com) 
     Commit Version: 1.6.0-1-g15f4949  Build Version: 1.6.7594.29634
     For more information, please see http://wiki.ros.org/sw_urdf_exporter -->
<robot
  name="butter_v33">
  
<!-- Adiciona o Plugin da Camera -->
  <gazebo reference="camera_link">
    <sensor type="camera" name="camera">
      <update_rate>30.0</update_rate>
      <camera name="head">   <!-- nao altere o nome onde esta escrito head -->
        <horizontal_fov>1.3962634</horizontal_fov>
        <image>
          <width>800</width>
          <height>800</height>
          <format>R8G8B8</format>
        </image>
        <clip>
          <near>0.02</near>
          <far>300</far>
        </clip>
        <noise>
          <type>gaussian</type>
          <mean>0.0</mean>
          <stddev>0.007</stddev>
        </noise>
      </camera>
      <plugin name="camera_controller" filename="libgazebo_ros_camera.so">
        <alwaysOn>true</alwaysOn>
        <updateRate>0.0</updateRate>
        <cameraName>/edrom_butter/camera</cameraName>
        <imageTopicName>image_raw</imageTopicName>
        <cameraInfoTopicName>camera_info</cameraInfoTopicName>
        <frameName>camera_link</frameName>
        <hackBaseline>0.07</hackBaseline>
        <distortionK1>0.0</distortionK1>
        <distortionK2>0.0</distortionK2>
        <distortionK3>0.0</distortionK3>
        <distortionT1>0.0</distortionT1>
        <distortionT2>0.0</distortionT2>
      </plugin>
    </sensor>
  </gazebo>

   <!-- Faz a camera aparecer no modelo -->
  <link name="camera_link">
    <visual>
      <origin xyz="0 0 0" rpy="0 0 0"/>
      <geometry>
    <box size="0.005 0.005 0.005"/>   <!-- Gera o tamanho do bloco que virtualiza a camera-->
      </geometry>
      <material name="red"/>
    </visual>

    <inertial>
      <mass value="1e-5" />
      <origin xyz="0 0 0" rpy="0 0 0"/>
      <inertia ixx="1e-6" ixy="0" ixz="0" iyy="1e-6" iyz="0" izz="1e-6" />
    </inertial>
  </link>
  
  <joint name="camera_joint" type="fixed">
    <axis xyz="0 0 1" />    
    <origin xyz="0.0 0.004 0.01375" rpy="0 -1.5708 0"/>   <!-- Ponto de origem e eixo de visualizacao da camera -->
    <parent link="head_link"/>   <!-- Vincula a referencia da peca a referencia da camera. Onde esta "head" adicione o nome da sua peca -->
    <child link="camera_link"/>
  </joint>

  <link
    name="base_link">
    <inertial>
      <origin
        xyz="0.012519 0.0034172 -4.3667E-18"
        rpy="0 0 0" />
      <mass
        value="0.0048494" />
      <inertia
        ixx="3.0192E-07"
        ixy="-5.6467E-23"
        ixz="1.7173E-23"
        iyy="4.6603E-07"
        iyz="3.0537E-23"
        izz="2.5641E-07" />
    </inertial>
    <visual>
      <origin
        xyz="0 0 0"
        rpy="0 0 0" />
      <geometry>
        <mesh
          filename="package://butter_v33/meshes/base_link.STL" />
      </geometry>
      <material
        name="">
        <color
          rgba="0.79216 0.81961 0.93333 1" />
      </material>
    </visual>
    <collision>
      <origin
        xyz="0 0 0"
        rpy="0 0 0" />
      <geometry>
        <mesh
          filename="package://butter_v33/meshes/base_link.STL" />
      </geometry>
    </collision>
  </link>
  <link
    name="motor_esq_tras_link">
    <inertial>
      <origin
        xyz="0.003 1.8605E-15 1.1418E-14"
        rpy="0 0 0" />
      <mass
        value="0.00018313" />
      <inertia
        ixx="1.7417E-09"
        ixy="-1.5376E-25"
        ixz="-4.2248E-25"
        iyy="1.3632E-09"
        iyz="2.3264E-25"
        izz="1.3632E-09" />
    </inertial>
    <visual>
      <origin
        xyz="0 0 0"
        rpy="0 0 0" />
      <geometry>
        <mesh
          filename="package://butter_v33/meshes/motor_esq_tras_link.STL" />
      </geometry>
      <material
        name="">
        <color
          rgba="0.79216 0.81961 0.93333 1" />
      </material>
    </visual>
    <collision>
      <origin
        xyz="0 0 0"
        rpy="0 0 0" />
      <geometry>
        <mesh
          filename="package://butter_v33/meshes/motor_esq_tras_link.STL" />
      </geometry>
    </collision>
  </link>
  <joint
    name="motor_esq_tras"
    type="continuous">
    <origin
      xyz="0.022519 0.014 0.0026087"
      rpy="-1.2783 0 0" />
    <parent
      link="base_link" />
    <child
      link="motor_esq_tras_link" />
    <axis
      xyz="1 0 0" />
  </joint>
  <link
    name="motor_esq_meio_link">
    <inertial>
      <origin
        xyz="0.003 -7.52978408791183E-16 -1.80411241501588E-16"
        rpy="0 0 0" />
      <mass
        value="0.000183131399115771" />
      <inertia
        ixx="1.74169018722331E-09"
        ixy="4.09234713889621E-26"
        ixz="3.15518349274499E-25"
        iyy="1.36323911008934E-09"
        iyz="3.10192729707385E-25"
        izz="1.36323911008934E-09" />
    </inertial>
    <visual>
      <origin
        xyz="0 0 0"
        rpy="0 0 0" />
      <geometry>
        <mesh
          filename="package://butter_v33/meshes/motor_esq_meio_link.STL" />
      </geometry>
      <material
        name="">
        <color
          rgba="0.792156862745098 0.819607843137255 0.933333333333333 1" />
      </material>
    </visual>
    <collision>
      <origin
        xyz="0 0 0"
        rpy="0 0 0" />
      <geometry>
        <mesh
          filename="package://butter_v33/meshes/motor_esq_meio_link.STL" />
      </geometry>
    </collision>
  </link>
  <joint
    name="motor_esq_meio"
    type="continuous">
    <origin
      xyz="0.022519 0 0.0026087"
      rpy="2.9064 0 0" />
    <parent
      link="base_link" />
    <child
      link="motor_esq_meio_link" />
    <axis
      xyz="1 0 0" />
  </joint>
  <link
    name="motor_esq_frente_Link">
    <inertial>
      <origin
        xyz="0.003 -3.73399228204008E-15 1.90993054705046E-15"
        rpy="0 0 0" />
      <mass
        value="0.000183131399115772" />
      <inertia
        ixx="1.74169018722331E-09"
        ixy="2.72121110596452E-25"
        ixz="5.96562719095E-26"
        iyy="1.36323911008934E-09"
        iyz="2.58493941422821E-25"
        izz="1.36323911008934E-09" />
    </inertial>
    <visual>
      <origin
        xyz="0 0 0"
        rpy="0 0 0" />
      <geometry>
        <mesh
          filename="package://butter_v33/meshes/motor_esq_frente_Link.STL" />
      </geometry>
      <material
        name="">
        <color
          rgba="0.792156862745098 0.819607843137255 0.933333333333333 1" />
      </material>
    </visual>
    <collision>
      <origin
        xyz="0 0 0"
        rpy="0 0 0" />
      <geometry>
        <mesh
          filename="package://butter_v33/meshes/motor_esq_frente_Link.STL" />
      </geometry>
    </collision>
  </link>
  <joint
    name="motor_esq_frente"
    type="continuous">
    <origin
      xyz="0.022519 -0.014 0.0026087"
      rpy="-1.2824 0 0" />
    <parent
      link="base_link" />
    <child
      link="motor_esq_frente_Link" />
    <axis
      xyz="1 0 0" />
  </joint>
  <link
    name="motor_dir_tras_link">
    <inertial>
      <origin
        xyz="-0.000481150670232955 -5.65519853168439E-15 -2.61075883134509E-15"
        rpy="0 0 0" />
      <mass
        value="0.000183131399115772" />
      <inertia
        ixx="1.74169018722331E-09"
        ixy="1.6372969393684E-25"
        ixz="1.37242809988697E-25"
        iyy="1.36323911008934E-09"
        iyz="3.36042123849667E-25"
        izz="1.36323911008933E-09" />
    </inertial>
    <visual>
      <origin
        xyz="0 0 0"
        rpy="0 0 0" />
      <geometry>
        <mesh
          filename="package://butter_v33/meshes/motor_dir_tras_link.STL" />
      </geometry>
      <material
        name="">
        <color
          rgba="0.792156862745098 0.819607843137255 0.933333333333333 1" />
      </material>
    </visual>
    <collision>
      <origin
        xyz="0 0 0"
        rpy="0 0 0" />
      <geometry>
        <mesh
          filename="package://butter_v33/meshes/motor_dir_tras_link.STL" />
      </geometry>
    </collision>
  </link>
  <joint
    name="motor_dir_tras"
    type="continuous">
    <origin
      xyz="0 0.014 0.0026087"
      rpy="-1.8137 0 0" />
    <parent
      link="base_link" />
    <child
      link="motor_dir_tras_link" />
    <axis
      xyz="1 0 0" />
  </joint>
  <link
    name="motor_dir_meio_link">
    <inertial>
      <origin
        xyz="-0.000481150670232952 -1.59746348094014E-15 -1.53631447841196E-15"
        rpy="0 0 0" />
      <mass
        value="0.000183131399115772" />
      <inertia
        ixx="1.74169018722331E-09"
        ixy="-8.31633363248937E-26"
        ixz="-5.4242781285591E-26"
        iyy="1.36323911008934E-09"
        iyz="4.13590306276514E-25"
        izz="1.36323911008934E-09" />
    </inertial>
    <visual>
      <origin
        xyz="0 0 0"
        rpy="0 0 0" />
      <geometry>
        <mesh
          filename="package://butter_v33/meshes/motor_dir_meio_link.STL" />
      </geometry>
      <material
        name="">
        <color
          rgba="0.792156862745098 0.819607843137255 0.933333333333333 1" />
      </material>
    </visual>
    <collision>
      <origin
        xyz="0 0 0"
        rpy="0 0 0" />
      <geometry>
        <mesh
          filename="package://butter_v33/meshes/motor_dir_meio_link.STL" />
      </geometry>
    </collision>
  </link>
  <joint
    name="motor_dir_meio"
    type="continuous">
    <origin
      xyz="0 0 0.0026087"
      rpy="-0.76654 0 0" />
    <parent
      link="base_link" />
    <child
      link="motor_dir_meio_link" />
    <axis
      xyz="1 0 0" />
  </joint>
  <link
    name="motor_dir_frente_link">
    <inertial>
      <origin
        xyz="-0.00048115067023296 3.04790914729125E-15 2.88311041707345E-15"
        rpy="0 0 0" />
      <mass
        value="0.000183131399115772" />
      <inertia
        ixx="1.74169018722331E-09"
        ixy="-4.08804314539374E-25"
        ixz="9.96318723210213E-27"
        iyy="1.36323911008934E-09"
        iyz="5.16987882845642E-25"
        izz="1.36323911008934E-09" />
    </inertial>
    <visual>
      <origin
        xyz="0 0 0"
        rpy="0 0 0" />
      <geometry>
        <mesh
          filename="package://butter_v33/meshes/motor_dir_frente_link.STL" />
      </geometry>
      <material
        name="">
        <color
          rgba="0.792156862745098 0.819607843137255 0.933333333333333 1" />
      </material>
    </visual>
    <collision>
      <origin
        xyz="0 0 0"
        rpy="0 0 0" />
      <geometry>
        <mesh
          filename="package://butter_v33/meshes/motor_dir_frente_link.STL" />
      </geometry>
    </collision>
  </link>
  <joint
    name="motor_dir_frente"
    type="continuous">
    <origin
      xyz="0 -0.014 0.0026087"
      rpy="-2.5119 0 0" />
    <parent
      link="base_link" />
    <child
      link="motor_dir_frente_link" />
    <axis
      xyz="1 0 0" />
  </joint>
  <link
    name="motor_base_link">
    <inertial>
      <origin
        xyz="0.0126163703657393 -0.0320016731668491 -0.00246282078418345"
        rpy="0 0 0" />
      <mass
        value="0.0124009744182285" />
      <inertia
        ixx="1.25475340607901E-06"
        ixy="6.72027782410902E-09"
        ixz="1.05202199799677E-09"
        iyy="1.26692127915553E-06"
        iyz="-9.25613501252401E-09"
        izz="1.68642011734325E-06" />
    </inertial>
    <visual>
      <origin
        xyz="0 0 0"
        rpy="0 0 0" />
      <geometry>
        <mesh
          filename="package://butter_v33/meshes/motor_base_link.STL" />
      </geometry>
      <material
        name="">
        <color
          rgba="0.792156862745098 0.819607843137255 0.933333333333333 1" />
      </material>
    </visual>
    <collision>
      <origin
        xyz="0 0 0"
        rpy="0 0 0" />
      <geometry>
        <mesh
          filename="package://butter_v33/meshes/motor_base_link.STL" />
      </geometry>
    </collision>
  </link>
  <joint
    name="motor_base"
    type="continuous">
    <origin
      xyz="0 0 0.015609"
      rpy="-1.5969 0 0" />
    <parent
      link="base_link" />
    <child
      link="motor_base_link" />
    <axis
      xyz="1 0 0" />
  </joint>
  <link
    name="motor_ombro_dir_link">
    <inertial>
      <origin
        xyz="0.00148730045602078 -0.0082214441696226 -0.00159221455047252"
        rpy="0 0 0" />
      <mass
        value="0.000426617038477361" />
      <inertia
        ixx="2.27702544704245E-08"
        ixy="-2.99500712883415E-10"
        ixz="-5.80031175899547E-11"
        iyy="2.83119823513615E-09"
        iyz="-3.58714763192266E-09"
        izz="2.06588262402105E-08" />
    </inertial>
    <visual>
      <origin
        xyz="0 0 0"
        rpy="0 0 0" />
      <geometry>
        <mesh
          filename="package://butter_v33/meshes/motor_ombro_dir_link.STL" />
      </geometry>
      <material
        name="">
        <color
          rgba="0.792156862745098 0.819607843137255 0.933333333333333 1" />
      </material>
    </visual>
    <collision>
      <origin
        xyz="0 0 0"
        rpy="0 0 0" />
      <geometry>
        <mesh
          filename="package://butter_v33/meshes/motor_ombro_dir_link.STL" />
      </geometry>
    </collision>
  </link>
  <joint
    name="motor_ombro_dir"
    type="continuous">
    <origin
      xyz="-0.0014838 -0.035426 0.00075"
      rpy="-0.11035 0 -3.1416" />
    <parent
      link="motor_base_link" />
    <child
      link="motor_ombro_dir_link" />
    <axis
      xyz="1 0 0" />
  </joint>
  <link
    name="motor_mao_dir_link">
    <inertial>
      <origin
        xyz="0 -0.009170088371685 -0.00156088656227564"
        rpy="0 0 0" />
      <mass
        value="0.000282173671532661" />
      <inertia
        ixx="8.06424998618971E-09"
        ixy="2.09380092552485E-24"
        ixz="-3.99498943914048E-26"
        iyy="7.1848587185355E-10"
        iyz="-6.09023571688409E-25"
        izz="8.33268958664053E-09" />
    </inertial>
    <visual>
      <origin
        xyz="0 0 0"
        rpy="0 0 0" />
      <geometry>
        <mesh
          filename="package://butter_v33/meshes/motor_mao_dir_link.STL" />
      </geometry>
      <material
        name="">
        <color
          rgba="0.792156862745098 0.819607843137255 0.933333333333333 1" />
      </material>
    </visual>
    <collision>
      <origin
        xyz="0 0 0"
        rpy="0 0 0" />
      <geometry>
        <mesh
          filename="package://butter_v33/meshes/motor_mao_dir_link.STL" />
      </geometry>
    </collision>
  </link>
  <joint
    name="motor_mao_dir"
    type="continuous">
    <origin
      xyz="0 -0.020029 -0.0038789"
      rpy="1.5708 -0.5519 -1.5708" />
    <parent
      link="motor_ombro_dir_link" />
    <child
      link="motor_mao_dir_link" />
    <axis
      xyz="0 0 1" />
  </joint>
  <link
    name="motor_ombro_esq_link">
    <inertial>
      <origin
        xyz="0.00148730045602078 -0.00822144416962261 -0.00159221455047252"
        rpy="0 0 0" />
      <mass
        value="0.000426617038477361" />
      <inertia
        ixx="2.27702544704244E-08"
        ixy="-2.99500712883414E-10"
        ixz="-5.80031175899543E-11"
        iyy="2.83119823513614E-09"
        iyz="-3.58714763192265E-09"
        izz="2.06588262402105E-08" />
    </inertial>
    <visual>
      <origin
        xyz="0 0 0"
        rpy="0 0 0" />
      <geometry>
        <mesh
          filename="package://butter_v33/meshes/motor_ombro_esq_link.STL" />
      </geometry>
      <material
        name="">
        <color
          rgba="0.792156862745098 0.819607843137255 0.933333333333333 1" />
      </material>
    </visual>
    <collision>
      <origin
        xyz="0 0 0"
        rpy="0 0 0" />
      <geometry>
        <mesh
          filename="package://butter_v33/meshes/motor_ombro_esq_link.STL" />
      </geometry>
    </collision>
  </link>
  <joint
    name="motor_ombro_esq"
    type="continuous">
    <origin
      xyz="0.026516 -0.035426 0.00075"
      rpy="2.8504 0 0" />
    <parent
      link="motor_base_link" />
    <child
      link="motor_ombro_esq_link" />
    <axis
      xyz="1 0 0" />
  </joint>
  <link
    name="motor_mao_esq_link">
    <inertial>
      <origin
        xyz="-3.46944695195361E-18 -0.009170088371685 -0.00156088656227564"
        rpy="0 0 0" />
      <mass
        value="0.000282173671532661" />
      <inertia
        ixx="8.0642499861897E-09"
        ixy="-1.008126371549E-24"
        ixz="6.98234600105972E-26"
        iyy="7.18485871853547E-10"
        iyz="-2.15995291301732E-24"
        izz="8.33268958664052E-09" />
    </inertial>
    <visual>
      <origin
        xyz="0 0 0"
        rpy="0 0 0" />
      <geometry>
        <mesh
          filename="package://butter_v33/meshes/motor_mao_esq_link.STL" />
      </geometry>
      <material
        name="">
        <color
          rgba="0.792156862745098 0.819607843137255 0.933333333333333 1" />
      </material>
    </visual>
    <collision>
      <origin
        xyz="0 0 0"
        rpy="0 0 0" />
      <geometry>
        <mesh
          filename="package://butter_v33/meshes/motor_mao_esq_link.STL" />
      </geometry>
    </collision>
  </link>
  <joint
    name="motor_mao_esq"
    type="continuous">
    <origin
      xyz="0 -0.020029 -0.0038789"
      rpy="-1.5708 -0.99863 1.5708" />
    <parent
      link="motor_ombro_esq_link" />
    <child
      link="motor_mao_esq_link" />
    <axis
      xyz="0 0 1" />
  </joint>
  <link
    name="head_link">
    <inertial>
      <origin
        xyz="-5.3544590432851E-07 0.00325324878272705 0.00993314928261171"
        rpy="0 0 0" />
      <mass
        value="0.0023883192065231" />
      <inertia
        ixx="8.05658847190811E-08"
        ixy="-3.60188987486368E-12"
        ixz="-4.54081939252092E-12"
        iyy="8.05771037072277E-08"
        iyz="2.23570055561495E-11"
        izz="6.72584956718303E-08" />
    </inertial>
    <visual>
      <origin
        xyz="0 0 0"
        rpy="0 0 0" />
      <geometry>
        <mesh
          filename="package://butter_v33/meshes/head_link.STL" />
      </geometry>
      <material
        name="">
        <color
          rgba="0.250980392156863 0.250980392156863 0.250980392156863 1" />
      </material>
    </visual>
    <collision>
      <origin
        xyz="0 0 0"
        rpy="0 0 0" />
      <geometry>
        <mesh
          filename="package://butter_v33/meshes/head_link.STL" />
      </geometry>
    </collision>
  </link>
  <joint
    name="head"
    type="fixed">
    <origin
      xyz="0.012461 -0.032427 -0.01375"
      rpy="-3.1416 0 0.049075" />
    <parent
      link="motor_base_link" />
    <child
      link="head_link" />
    <axis
      xyz="0 0 0" />
  </joint>
</robot>
