<?xml version="1.0" encoding="utf-8"?>
<!-- This URDF was automatically created by SolidWorks to URDF Exporter! Originally created by Stephen Brawner (brawner@gmail.com) 
     Commit Version: 1.5.1-0-g916b5db  Build Version: 1.5.7152.31018
     For more information, please see http://wiki.ros.org/sw_urdf_exporter -->
<robot
  name="butter_robot_edrom_version">
  
<!-- Adiciona o Plugin da Camera -->
  <gazebo reference="camera_link">
    <sensor type="camera" name="camera">
      <update_rate>30.0</update_rate>
      <camera name="head">   <!-- nao altere o nome onde esta escrito head -->
        <horizontal_fov>1.3962634</horizontal_fov>
        <image>
          <width>800</width>
          <height>800</height>
          <format>R8G8B8</format>
        </image>
        <clip>
          <near>0.02</near>
          <far>300</far>
        </clip>
        <noise>
          <type>gaussian</type>
          <mean>0.0</mean>
          <stddev>0.007</stddev>
        </noise>
      </camera>
      <plugin name="camera_controller" filename="libgazebo_ros_camera.so">
        <alwaysOn>true</alwaysOn>
        <updateRate>0.0</updateRate>
        <cameraName>/frank/camera</cameraName>
        <imageTopicName>image_raw</imageTopicName>
        <cameraInfoTopicName>camera_info</cameraInfoTopicName>
        <frameName>camera_link</frameName>
        <hackBaseline>0.07</hackBaseline>
        <distortionK1>0.0</distortionK1>
        <distortionK2>0.0</distortionK2>
        <distortionK3>0.0</distortionK3>
        <distortionT1>0.0</distortionT1>
        <distortionT2>0.0</distortionT2>
      </plugin>
    </sensor>
  </gazebo>

   <!-- Faz a camera aparecer no modelo -->
  <link name="camera_link">
    <visual>
      <origin xyz="0 0 0" rpy="0 0 0"/>
      <geometry>
    <box size="0.01 0.01 0.01"/>   <!-- Gera o tamanho do bloco que virtualiza a camera-->
      </geometry>
      <material name="red"/>
    </visual>

    <inertial>
      <mass value="1e-5" />
      <origin xyz="0 0 0" rpy="0 0 0"/>
      <inertia ixx="1e-6" ixy="0" ixz="0" iyy="1e-6" iyz="0" izz="1e-6" />
    </inertial>
  </link>
  
  <joint name="camera_joint" type="fixed">
    <axis xyz="0 0 1" />
    <origin xyz="0.00429900271088217 -0.0600078441942872 0.0554853797911345" rpy="3.1410 3.1410 1.5707"/>   <!-- Ponto de origem e eixo de visualizacao da camera -->
    <parent link="base_link"/>   <!-- Vincula a referencia da peca a referencia da camera. Onde esta "head" adicione o nome da sua peca -->
    <child link="camera_link"/>
  </joint>
  
  
  <link
    name="base_link">
    <inertial>
      <origin
        xyz="0.00429900271088217 0.000330078441942872 0.0554853797911345"
        rpy="0 0 0" />
      <mass
        value="0.00393574329414396" />
      <inertia
        ixx="4.49832345221081E-07"
        ixy="5.57169857796941E-09"
        ixz="1.28918769379355E-09"
        iyy="6.54451885162872E-07"
        iyz="1.46565294484842E-08"
        izz="3.11672940536797E-07" />
    </inertial>
    <visual>
      <origin
        xyz="0 0 0"
        rpy="0 0 0" />
      <geometry>
        <mesh
          filename="package://butter_robot_edrom_version/meshes/base_link.STL" />
      </geometry>
      <material
        name="">
        <color
          rgba="0.792156862745098 0.819607843137255 0.933333333333333 1" />
      </material>
    </visual>
    <collision>
      <origin
        xyz="0 0 0"
        rpy="0 0 0" />
      <geometry>
        <mesh
          filename="package://butter_robot_edrom_version/meshes/base_link.STL" />
      </geometry>
    </collision>
  </link>
  <link
    name="roda_dir_inf_Link">
    <inertial>
      <origin
        xyz="0 6.50521303491303E-19 -0.00207370804147"
        rpy="0 0 0" />
      <mass
        value="0.000401432525904627" />
      <inertia
        ixx="4.54808924620685E-09"
        ixy="0"
        ixz="1.29731646851578E-24"
        iyy="4.55489666187263E-09"
        iyz="-7.83155863154453E-25"
        izz="8.035651654256E-09" />
    </inertial>
    <visual>
      <origin
        xyz="0 0 0"
        rpy="0 0 0" />
      <geometry>
        <mesh
          filename="package://butter_robot_edrom_version/meshes/roda_dir_inf_Link.STL" />
      </geometry>
      <material
        name="">
        <color
          rgba="0.792156862745098 0.819607843137255 0.933333333333333 1" />
      </material>
    </visual>
    <collision>
      <origin
        xyz="0 0 0"
        rpy="0 0 0" />
      <geometry>
        <mesh
          filename="package://butter_robot_edrom_version/meshes/roda_dir_inf_Link.STL" />
      </geometry>
    </collision>
  </link>
  <joint
    name="roda_dir_inf"
    type="continuous">
    <origin
      xyz="-0.00909432320128014 -0.045333574135654 -0.000632028552777854"
      rpy="1.59846873515134 -0.0289421046717752 1.56359268525581" />
    <parent
      link="base_link" />
    <child
      link="roda_dir_inf_Link" />
    <axis
      xyz="0 0 1" />
  </joint>
  <link
    name="roda_esq_inf_Link">
    <inertial>
      <origin
        xyz="-6.93889390390723E-18 4.33680868994202E-19 0.00207373662201797"
        rpy="0 0 0" />
      <mass
        value="0.000401432525904627" />
      <inertia
        ixx="4.54808924620684E-09"
        ixy="7.10858338912758E-26"
        ixz="2.13903736527385E-24"
        iyy="4.55489666187263E-09"
        iyz="3.13373416877236E-25"
        izz="8.03565165425599E-09" />
    </inertial>
    <visual>
      <origin
        xyz="0 0 0"
        rpy="0 0 0" />
      <geometry>
        <mesh
          filename="package://butter_robot_edrom_version/meshes/roda_esq_inf_Link.STL" />
      </geometry>
      <material
        name="">
        <color
          rgba="0.792156862745098 0.819607843137255 0.933333333333333 1" />
      </material>
    </visual>
    <collision>
      <origin
        xyz="0 0 0"
        rpy="0 0 0" />
      <geometry>
        <mesh
          filename="package://butter_robot_edrom_version/meshes/roda_esq_inf_Link.STL" />
      </geometry>
    </collision>
  </link>
  <joint
    name="roda_esq_inf"
    type="continuous">
    <origin
      xyz="0.0177474098827506 -0.0455054347416066 -0.00137469744145888"
      rpy="1.59845853450625 -0.0100284554753815 1.56411620014391" />
    <parent
      link="base_link" />
    <child
      link="roda_esq_inf_Link" />
    <axis
      xyz="0 0 1" />
  </joint>
  <link
    name="roda_dir_fre_Link">
    <inertial>
      <origin
        xyz="-1.38777878078145E-17 2.38524477946811E-18 -0.00207370804146999"
        rpy="0 0 0" />
      <mass
        value="0.000401432525904627" />
      <inertia
        ixx="4.54808924620685E-09"
        ixy="-3.87740912134232E-26"
        ixz="-3.8160168102544E-24"
        iyy="4.55489666187263E-09"
        iyz="-3.77845440939139E-24"
        izz="8.035651654256E-09" />
    </inertial>
    <visual>
      <origin
        xyz="0 0 0"
        rpy="0 0 0" />
      <geometry>
        <mesh
          filename="package://butter_robot_edrom_version/meshes/roda_dir_fre_Link.STL" />
      </geometry>
      <material
        name="">
        <color
          rgba="0.792156862745098 0.819607843137255 0.933333333333333 1" />
      </material>
    </visual>
    <collision>
      <origin
        xyz="0 0 0"
        rpy="0 0 0" />
      <geometry>
        <mesh
          filename="package://butter_robot_edrom_version/meshes/roda_dir_fre_Link.STL" />
      </geometry>
    </collision>
  </link>
  <joint
    name="roda_dir_fre"
    type="continuous">
    <origin
      xyz="-0.00924578576017018 -0.0653149154667465 -0.00148235655045012"
      rpy="1.59846873515134 -0.0289421046717683 1.56359268525582" />
    <parent
      link="base_link" />
    <child
      link="roda_dir_fre_Link" />
    <axis
      xyz="0 0 1" />
  </joint>
  <link
    name="roda_esq_frent_Link">
    <inertial>
      <origin
        xyz="-1.38777878078145E-17 -1.73472347597681E-18 0.0020596481580519"
        rpy="0 0 0" />
      <mass
        value="0.000401432525904627" />
      <inertia
        ixx="4.54808924620685E-09"
        ixy="2.58493941422821E-25"
        ixz="-1.06628750836914E-25"
        iyy="4.55489666187263E-09"
        iyz="-8.87058310702923E-25"
        izz="8.035651654256E-09" />
    </inertial>
    <visual>
      <origin
        xyz="0 0 0"
        rpy="0 0 0" />
      <geometry>
        <mesh
          filename="package://butter_robot_edrom_version/meshes/roda_esq_frent_Link.STL" />
      </geometry>
      <material
        name="">
        <color
          rgba="0.792156862745098 0.819607843137255 0.933333333333333 1" />
      </material>
    </visual>
    <collision>
      <origin
        xyz="0 0 0"
        rpy="0 0 0" />
      <geometry>
        <mesh
          filename="package://butter_robot_edrom_version/meshes/roda_esq_frent_Link.STL" />
      </geometry>
    </collision>
  </link>
  <joint
    name="roda_esq_frent"
    type="continuous">
    <origin
      xyz="0.0176100301098227 -0.0654868662410991 -0.00222541508785343"
      rpy="-1.59849870437435 -0.0547771462049383 -1.57568189273198" />
    <parent
      link="base_link" />
    <child
      link="roda_esq_frent_Link" />
    <axis
      xyz="0 0 1" />
  </joint>
  <link
    name="junta_inf_Link">
    <inertial>
      <origin
        xyz="-0.00520984743524376 -0.0319093643038402 0.00283033734053024"
        rpy="0 0 0" />
      <mass
        value="0.0126761209831532" />
      <inertia
        ixx="1.25924346591142E-06"
        ixy="-6.72218283521542E-09"
        ixz="1.05272765146392E-09"
        iyy="1.2665127702767E-06"
        iyz="9.29174578622249E-09"
        izz="1.69119198168719E-06" />
    </inertial>
    <visual>
      <origin
        xyz="0 0 0"
        rpy="0 0 0" />
      <geometry>
        <mesh
          filename="package://butter_robot_edrom_version/meshes/junta_inf_Link.STL" />
      </geometry>
      <material
        name="">
        <color
          rgba="0.792156862745098 0.819607843137255 0.933333333333333 1" />
      </material>
    </visual>
    <collision>
      <origin
        xyz="0 0 0"
        rpy="0 0 0" />
      <geometry>
        <mesh
          filename="package://butter_robot_edrom_version/meshes/junta_inf_Link.STL" />
      </geometry>
    </collision>
  </link>
  <joint
    name="junta_inf"
    type="continuous">
    <origin
      xyz="0 -0.0559783796570403 0.0126818729036873"
      rpy="-1.62635175793315 -0.0276608163751402 3.13519000227837" />
    <parent
      link="base_link" />
    <child
      link="junta_inf_Link" />
    <axis
      xyz="1 0 0" />
  </joint>
  <link
    name="braco_esq_Link">
    <inertial>
      <origin
        xyz="0.00285549620586977 -0.013182698362745 -0.00102414846371802"
        rpy="0 0 0" />
      <mass
        value="0.000686513662248718" />
      <inertia
        ixx="7.68647126234043E-08"
        ixy="5.62411236956801E-10"
        ixz="2.37389600875504E-11"
        iyy="5.95748944372461E-09"
        iyz="3.14751989963956E-09"
        izz="7.23481174935265E-08" />
    </inertial>
    <visual>
      <origin
        xyz="0 0 0"
        rpy="0 0 0" />
      <geometry>
        <mesh
          filename="package://butter_robot_edrom_version/meshes/braco_esq_Link.STL" />
      </geometry>
      <material
        name="">
        <color
          rgba="0.792156862745098 0.819607843137255 0.933333333333333 1" />
      </material>
    </visual>
    <collision>
      <origin
        xyz="0 0 0"
        rpy="0 0 0" />
      <geometry>
        <mesh
          filename="package://butter_robot_edrom_version/meshes/braco_esq_Link.STL" />
      </geometry>
    </collision>
  </link>
  <joint
    name="braco_esq"
    type="continuous">
    <origin
      xyz="-0.0178240805318439 -0.0354260756077894 -0.000749940320395943"
      rpy="-0.203708900614049 0 3.14159265358979" />
    <parent
      link="junta_inf_Link" />
    <child
      link="braco_esq_Link" />
    <axis
      xyz="1 0 0" />
  </joint>
  <link
    name="braco_dir_Link">
    <inertial>
      <origin
        xyz="-0.00260519959050656 -0.0131370060205366 -0.00102360210972865"
        rpy="0 0 0" />
      <mass
        value="0.000584067976024174" />
      <inertia
        ixx="6.55456446981842E-08"
        ixy="-5.16733951841109E-10"
        ixz="-2.31927861365446E-11"
        iyy="4.92474058166378E-09"
        iyz="2.61591498057086E-09"
        izz="6.1546878119059E-08" />
    </inertial>
    <visual>
      <origin
        xyz="0 0 0"
        rpy="0 0 0" />
      <geometry>
        <mesh
          filename="package://butter_robot_edrom_version/meshes/braco_dir_Link.STL" />
      </geometry>
      <material
        name="">
        <color
          rgba="0.792156862745098 0.819607843137255 0.933333333333333 1" />
      </material>
    </visual>
    <collision>
      <origin
        xyz="0 0 0"
        rpy="0 0 0" />
      <geometry>
        <mesh
          filename="package://butter_robot_edrom_version/meshes/braco_dir_Link.STL" />
      </geometry>
    </collision>
  </link>
  <joint
    name="braco_dir"
    type="continuous">
    <origin
      xyz="0.0075475031519509 -0.0354260756077949 -0.000749940320397491"
      rpy="-0.16604963710819 0 3.14159265358979" />
    <parent
      link="junta_inf_Link" />
    <child
      link="braco_dir_Link" />
    <axis
      xyz="1 0 0" />
  </joint>
</robot>
